D:\Desktop\JobAssistantAgent\extract_utils.py:11: RuntimeWarning: coroutine 'UploadFile.read' was never awaited  return "Failed to extract PDF text."
RuntimeWarning: Enable tracemalloc to get the object allocation traceback
‚ùå Selenium error: Message: 
Stacktrace:
        GetHandleVerifier [0x0xdc44a3+62419]
        GetHandleVerifier [0x0xdc44e4+62484]
        (No symbol) [0x0xc02133]
        (No symbol) [0x0xc4a8fe]
        (No symbol) [0x0xc4ac9b]
        (No symbol) [0x0xc93052]
        (No symbol) [0x0xc6f4b4]
        (No symbol) [0x0xc9087a]
        (No symbol) [0x0xc6f266]
        (No symbol) [0x0xc3e852]
        (No symbol) [0x0xc3f6f4]
        GetHandleVerifier [0x0x1034793+2619075]
        GetHandleVerifier [0x0x102fbaa+2599642]
        GetHandleVerifier [0x0xdeb04a+221050]
        GetHandleVerifier [0x0xddb2c8+156152]
        GetHandleVerifier [0x0xde1c7d+183213]
        GetHandleVerifier [0x0xdcc388+94904]
        GetHandleVerifier [0x0xdcc512+95298]
        GetHandleVerifier [0x0xdb766a+9626]
        BaseThreadInitThunk [0x0x76fcfcc9+25]
        RtlGetAppContainerNamedObjectPath [0x0x778c809e+286]
        RtlGetAppContainerNamedObjectPath [0x0x778c806e+238]

INFO:     127.0.0.1:62223 - "POST /score-from-inputs HTTP/1.1" 500 Internal Server Error
ERROR:    Exception in ASGI application
Traceback (most recent call last):
  File "C:\Users\Hemanth\AppData\Roaming\Python\Python312\site-packages\uvicorn\protocols\http\h11_impl.py", line 403, in run_asgi
    result = await app(  # type: ignore[func-returns-value]
             ^^^^^^^^^^^^^^^^^^^^^^^^^^^^^^^^^^^^^^^^^^^^^^
  File "C:\Users\Hemanth\AppData\Roaming\Python\Python312\site-packages\uvicorn\middleware\proxy_headers.py", line 60, in __call__
    return await self.app(scope, receive, send)
           ^^^^^^^^^^^^^^^^^^^^^^^^^^^^^^^^^^^^
  File "C:\Users\Hemanth\AppData\Roaming\Python\Python312\site-packages\fastapi\applications.py", line 1054, in __call__
    await super().__call__(scope, receive, send)
  File "C:\Users\Hemanth\AppData\Roaming\Python\Python312\site-packages\starlette\applications.py", line 112, in __call__
    await self.middleware_stack(scope, receive, send)
  File "C:\Users\Hemanth\AppData\Roaming\Python\Python312\site-packages\starlette\middleware\errors.py", line 187, in __call__
    raise exc
  File "C:\Users\Hemanth\AppData\Roaming\Python\Python312\site-packages\starlette\middleware\errors.py", line 165, in __call__
    await self.app(scope, receive, _send)
  File "C:\Users\Hemanth\AppData\Roaming\Python\Python312\site-packages\starlette\middleware\exceptions.py", line 62, in __call__
    await wrap_app_handling_exceptions(self.app, conn)(scope, receive, send)
  File "C:\Users\Hemanth\AppData\Roaming\Python\Python312\site-packages\starlette\_exception_handler.py", line 
53, in wrapped_app
    raise exc
  File "C:\Users\Hemanth\AppData\Roaming\Python\Python312\site-packages\starlette\_exception_handler.py", line 
42, in wrapped_app
    await app(scope, receive, sender)
  File "C:\Users\Hemanth\AppData\Roaming\Python\Python312\site-packages\starlette\routing.py", line 714, in __call__
    await self.middleware_stack(scope, receive, send)
  File "C:\Users\Hemanth\AppData\Roaming\Python\Python312\site-packages\starlette\routing.py", line 734, in app    await route.handle(scope, receive, send)
  File "C:\Users\Hemanth\AppData\Roaming\Python\Python312\site-packages\starlette\routing.py", line 288, in handle
    await self.app(scope, receive, send)
  File "C:\Users\Hemanth\AppData\Roaming\Python\Python312\site-packages\starlette\routing.py", line 76, in app 
    await wrap_app_handling_exceptions(app, request)(scope, receive, send)
  File "C:\Users\Hemanth\AppData\Roaming\Python\Python312\site-packages\starlette\_exception_handler.py", line 
53, in wrapped_app
    raise exc
  File "C:\Users\Hemanth\AppData\Roaming\Python\Python312\site-packages\starlette\_exception_handler.py", line 
42, in wrapped_app
    await app(scope, receive, sender)
  File "C:\Users\Hemanth\AppData\Roaming\Python\Python312\site-packages\starlette\routing.py", line 73, in app 
    response = await f(request)
               ^^^^^^^^^^^^^^^^
  File "C:\Users\Hemanth\AppData\Roaming\Python\Python312\site-packages\fastapi\routing.py", line 301, in app  
    raw_response = await run_endpoint_function(
                   ^^^^^^^^^^^^^^^^^^^^^^^^^^^^
  File "C:\Users\Hemanth\AppData\Roaming\Python\Python312\site-packages\fastapi\routing.py", line 212, in run_endpoint_function
    return await dependant.call(**values)
           ^^^^^^^^^^^^^^^^^^^^^^^^^^^^^^
  File "D:\Desktop\JobAssistantAgent\main.py", line 48, in score_from_inputs
    result = score_resume(jd_text, resume_text)
             ^^^^^^^^^^^^^^^^^^^^^^^^^^^^^^^^^^
  File "D:\Desktop\JobAssistantAgent\resume_utils.py", line 23, in score_resume
    response = client.chat.completions.create(
               ^^^^^^^^^^^^^^^^^^^^^^^^^^^^^^^
  File "C:\Users\Hemanth\AppData\Roaming\Python\Python312\site-packages\openai\_utils\_utils.py", line 287, in 
wrapper
    return func(*args, **kwargs)
           ^^^^^^^^^^^^^^^^^^^^^
  File "C:\Users\Hemanth\AppData\Roaming\Python\Python312\site-packages\openai\resources\chat\completions\completions.py", line 1087, in create
    return self._post(
           ^^^^^^^^^^^
  File "C:\Users\Hemanth\AppData\Roaming\Python\Python312\site-packages\openai\_base_client.py", line 1249, in 
post
    return cast(ResponseT, self.request(cast_to, opts, stream=stream, stream_cls=stream_cls))
                           ^^^^^^^^^^^^^^^^^^^^^^^^^^^^^^^^^^^^^^^^^^^^^^^^^^^^^^^^^^^^^^^^^
  File "C:\Users\Hemanth\AppData\Roaming\Python\Python312\site-packages\openai\_base_client.py", line 1037, in 
request
    raise self._make_status_error_from_response(err.response) from None
openai.AuthenticationError: Error code: 401 - {'error': {'message': 'Invalid API Key', 'type': 'invalid_request_error', 'code': 'invalid_api_key'}}
